Workbook

Sheet Liste
A1: Mot | B1: Définition | C1: Courte | D1: Jour | E1: Alea
A2: Quérimonie | B2: (ké-ri-mo-nie), n. f. 1°Terme d’officialité. Requête présentée au juge d’église, pour obtenir la permission d’adresser un monitoire. 2°Familièrement. Il s’est dit pour plainte en général. Finissez, finissez votre quérimonie, SCARRON. Après une longue et furieuse quérimonie, Mme de Roquelaure commença à découvrir le fait, SAINT-SIMON. | C2: Plainte solennelle ou doléance formulée par écrit en justice ou en liturgie. | D2: =TODAY()+1 -> 46168 | E2: 0.0082714884
A3: Concraire | B3: (kon-krê-r’), v. a. Terme de grammaire et de logique. Donner le caractère concret, par opposition à abstraire. | C3: Résister, s'opposer fermement à quelque chose en vieux français. | D3: =D2+1 -> 46169 | E3: 0.97748689
A4: Écornifleur | B4: Personne qui profite de la générosité des autres sans jamais rendre la pareille. | C4: Parasite, pique-assiette qui vit aux crochets des autres en quémandant. | D4: =D3+1 -> 46170 | E4: 0.63241814
A5: Valetet | B5: (va-le-tè), n. m. Nom donné au bord latéral du filet de pêche, Décret du 7 juin 1852. | C5: (ou Valeton) Jeune valet ou serviteur de bas étage au Moyen Âge (vieux français). | D5: =D4+1 -> 46171 | E5: 0.25508909
A6: Ganja | B6: (gan-ja), n. m. Préparation qui se fait avec les fleurs séchées du chanvre indien, Journ. offic. 5 janv. 1873, p. 58,1re col. | C6: Nom traditionnel d'origine indienne donné au chanvre indien (cannabis). | D6: =D5+1 -> 46172 | E6: 0.36623996
A7: Girie | B7: (ji-rie), n. f. Terme populaire. Plainte hypocrite, jérémiade ridicule. | C7: Plainte affectée, fausse jérémiade ou manières hypocrites pour attirer la pitié (surtout au pluriel giries). | D7: =D6+1 -> 46173 | E7: 0.5196653
A8: Docte | B8: (do-kt’), adj. Instruit, versé en toute sorte de connaissances littéraires. L’homme docte sert moins que l’homme pacifique, CORNEILLE. Par raillerie, une docte matrone, une femme savante. | C8: Qui possède un savoir approfondi, une grande érudition classique. | D8: =D7+1 -> 46174 | E8: 0.92564477
A9: Isocolon | B9: (i-zo-ko-lon), n. m. Terme de rhétorique. Période dont les membres sont égaux. | C9: Figure de style caractérisée par des membres de phrases de longueur et de structure grammaticale identiques. | D9: =D8+1 -> 46175 | E9: 0.74405275
A10: Oing | B10: (ouin ; le g ne se prononce jamais), n. m. Graisse. L’oing, qu’on appelle autrement axonge, est la graisse la plus molle et la plus humide du corps des animaux. | C10: (ou Vieux oing) Graisse de porc ou de bête purifiée servant à lubrifier les essieux des charrettes autrefois. | D10: =D9+1 -> 46176 | E10: 0.039787165
A11: Bonnette | B11: (bo-nè-t’), n. f. 1°Terme de fortification. Ouvrage avancé qui est au delà de la contrescarpe, en forme de petit corps de garde, et dont les deux faces forment un angle saillant 2°Terme de marine. Petites voiles qu’on ajoute aux grandes pour présenter une plus grande surface au vent. | C11: Voile additionnelle que l'on lace aux grandes voiles par beau temps pour augmenter la vitesse. | D11: =D10+1 -> 46177 | E11: 1.0397872
A12: Muant | B12: (mu-an), n. m. Bassin qui fait partie d’un marais salant. | C12: Animal ou oiseau qui est en période de mue, perdant ses poils ou ses plumes. | D12: =D11+1 -> 46178 | E12: 2.0397872
A13: Leu | B13: (leu), n. m. Ancien nom du loup. Usité seulement dans cette locution familière : à la queue leu leu, à la suite les uns des autres. | C13: Ancien mot de vieux français pour désigner le loup (utilisé dans "à la queue leu leu"). | D13: =D12+1 -> 46179 | E13: 3.0397872
A14: Mantelet | B14: (man-te-lè), n. m. Machine de guerre composée de madriers qu’on poussait devant soi pour se couvrir dans l’attaque des places. Sous de forts mantelets et d’épais gabions Elle vient s’attacher au pied des bastions, BRÉBEUF. | C14: Court manteau de femme sans manches ; ou lourd panneau de bois mobile protégeant les assiégeants. | D14: =D13+1 -> 46180 | E14: 4.0397872
... A1967: Quadrivium | B1967: (koua-dri-vi-om’), n. m. La division supérieure des sept arts dans l’université du moyen âge, division qui venait après le trivium et qui comprenait l’arithmétique, la géométrie, la musique et l’astronomie. | C1967: Les quatre sciences de l'enseignement supérieur médiéval comprenant l'arithmétique, la géométrie, l'astronomie et la musique. | D1967: =D1966+1 -> 48133 | E1967: 1957.0398
A1968: Exégète (s) | B1968: (è-gzé-jé-t’), n. m. Savant qui se consacre à l’explication et à l’interprétation des livres saints. | C1968: #N/A | D1968: =D1967+1 -> 48134 | E1968: 1958.0398
A1969: Vulpin | B1969: INE (vul-pin, pi-n’), adj. 1°Qui tient du renard 2°N. m. Terme de botanique. Genre de la famille des graminées. Vulpin, nommé aussi racouet, plante ainsi dite du latin vulpis, parce que l’épi est comparé à une queue de renard. | C1969: (Queue-de-rat) Plante herbeuse commune des prairies dont l'épi allongé ressemble à la queue d'un renard. | D1969: =D1968+1 -> 48135 | E1969: 1959.0398
A1970: Patrologie | B1970: (pa-tro-lo-jie), n. f. Connaissance particulière des Pères de l’Eglise. Édition de tous les Pères de l’Église. | C1970: Étude historique et théologique de la vie, des œuvres et des doctrines des Pères de l'Église. | D1970: =D1969+1 -> 48136 | E1970: 1960.0398
A1971: Avalaige | B1971: n. m. Pente douce, chemin pour descendre. (La Curne) | C1971: Action de descendre un cours d'eau en bateau ou de faire flotter du bois. | D1971: =D1970+1 -> 48137 | E1971: 1961.0398
A1972: Hobin | B1972: (ho-bin), n. m. Nom d’une race de chevaux d’Écosse qui vont naturellement l’amble. | C1972: Ancien cheval de selle écossais, d'allure rapide et d'une petite taille. | D1972: =D1971+1 -> 48138 | E1972: 1962.0398
A1973: Quartier-mestre | B1973: (kar-tié-mè-str’), n. m. Nom que l’on donnait autrefois au maréchal des logis d’un régiment de cavalerie étrangère. | C1973: Sous-officier de marine chargé des détails d'administration, des vivres ou de la manœuvre. | D1973: =D1972+1 -> 48139 | E1973: 1963.0398
A1974: Paillau | B1974: n. m. Portion. (La Curne) | C1974: (ou Paillot) Petit lit de paille, paillasse rustique ou natte de marin. | D1974: =D1973+1 -> 48140 | E1974: 1964.0398
A1975: Were | B1975: n. f. Guerre. " Grans pais, koi c’on die, Gist en grande were à le fie. " (Vatic. 1490, La Curne.) | C1975: Digue de terre ou barrage en maçonnerie construit le long d'une rivière en vieux français. | D1975: =D1974+1 -> 48141 | E1975: 1965.0398
A1976: Hétérobaphie | B1976: (é-té-ro-ba-fie), n. f. État d’un corps dont la surface est de deux ou de plusieurs couleurs. | C1976: Propriété d'un corps ou d'un tissu présentant des nuances de couleurs variées ou changeantes. | D1976: =D1975+1 -> 48142 | E1976: 1966.0398
A1977: Hague | B1977: (ha-gh’, h aspirée), n. f. Palissade. | C1977: Clôture faite de pieux de bois ou haie vive en vieux français régional. | D1977: =D1976+1 -> 48143 | E1977: 1967.0398
A1978: Rumb | B1978: (ronb’), n. m. 1°Terme de marine. Quantité angulaire comprise entre deux des trente-deux aires de vent de la boussole 2°Ligne de rumb, courbe que décrit un vaisseau, en faisant toujours le même angle avec le méridien. | C1978: Angle de cap mesurant 11°15', correspondant à l'une des 32 divisions de la rose des vents. | D1978: =D1977+1 -> 48144 | E1978: 1968.0398
A1979: Houka | B1979: (hou-ka), n. m. Pipe turque ou persane, peu différente du narghileh. | C1979: (ou Narguilé) Pipe orientale à eau dotée d'un long tuyau flexible pour fumer le tabac. | D1979: =D1978+1 -> 48145 | E1979: 1969.0398
A1980: Acrologique | B1980: (a-kro-lo-ji-k’), adj. Terme de grammaire. Qui appartient au commencement d’un mot. | C1980: Qui concerne l'utilisation de la première lettre d'un mot pour en représenter le son. | D1980: =D1979+1 -> 48146 | E1980: 1970.0398
... A4978: Bistourner | B4978: (bi-stour-né), v. t. 1°Tourner, courber un objet de manière à le déformer 2°Terme de vétérinaire. Châtrer un animal en tordant les vaisseaux testiculaires 3°Se bistourner, v. pr. Devenir bistourné. Ses jambes se sont bistournées. | C4978: Tordre un objet ; ou castrer un animal par torsion des vaisseaux sans incision. | D4978: =D4977+1 -> 51144 | E4978: 4968.0398

Sheet Feuil1
A1: Abscons : Très difficile à comprendre ; obscur, nébuleux. | B1: =LEN(A1) -> 61 | C1: =SEARCH(":",A1) -> 13 | D1: =LEFT(A1,C1-2) -> Abscons | E1: =LEN(D1) -> 11 | F1: Abscons | G1: Très difficile à comprendre ; obscur, nébuleux. | H1: =MATCH(F1,Liste!A:A,0) -> #N/A
A2: Alacrité : Gaieté vive et entraînante ; entrain. | B2: =LEN(A2) -> 52 | C2: =SEARCH(":",A2) -> 14 | D2: =LEFT(A2,C2-2) -> Alacrité | E2: =LEN(D2) -> 12 | F2: Alacrité | G2: Gaieté vive et entraînante ; entrain. | H2: =MATCH(F2,Liste!A:A,0) -> 1768
A3: Captieux : Qui cherche à tromper ou induire en erreur sous des apparences séduisantes. | B3: =LEN(A3) -> 90 | C3: =SEARCH(":",A3) -> 14 | D3: =LEFT(A3,C3-2) -> Captieux | E3: =LEN(D3) -> 12 | F3: Captieux | G3: Qui cherche à tromper ou induire en erreur sous des apparences séduisantes. | H3: =MATCH(F3,Liste!A:A,0) -> 3706
A4: Contempteur : Personne qui dénigre, méprise ou critique vivement. | B4: =LEN(A4) -> 69 | C4: =SEARCH(":",A4) -> 17 | D4: =LEFT(A4,C4-2) -> Contempteur | E4: =LEN(D4) -> 15 | F4: Contempteur | G4: Personne qui dénigre, méprise ou critique vivement. | H4: =MATCH(F4,Liste!A:A,0) -> 993
A5: Diatribe : Critique violente, amère et passionnée contre quelqu'un ou quelque chose. | B5: =LEN(A5) -> 88 | C5: =SEARCH(":",A5) -> 14 | D5: =LEFT(A5,C5-2) -> Diatribe | E5: =LEN(D5) -> 12 | F5: Diatribe | G5: Critique violente, amère et passionnée contre quelqu'un ou quelque chose. | H5: =MATCH(F5,Liste!A:A,0) -> #N/A
A6: Dilemme : Obligation de choisir entre deux partis comprenant tous deux des inconvénients. | B6: =LEN(A6) -> 93 | C6: =SEARCH(":",A6) -> 13 | D6: =LEFT(A6,C6-2) -> Dilemme | E6: =LEN(D6) -> 11 | F6: Dilemme | G6: Obligation de choisir entre deux partis comprenant tous deux des inconvénients. | H6: =MATCH(F6,Liste!A:A,0) -> #N/A
A7: Éburnéen : Qui a la blancheur ou la texture de l'ivoire. | B7: =LEN(A7) -> 60 | C7: =SEARCH(":",A7) -> 14 | D7: =LEFT(A7,C7-2) -> Éburnéen | E7: =LEN(D7) -> 12 | F7: Éburnéen | G7: Qui a la blancheur ou la texture de l'ivoire. | H7: =MATCH(F7,Liste!A:A,0) -> 4935
A8: Éristique : Art de la controverse, de la dispute philosophique. | B8: =LEN(A8) -> 67 | C8: =SEARCH(":",A8) -> 15 | D8: =LEFT(A8,C8-2) -> Éristique | E8: =LEN(D8) -> 13 | F8: Éristique | G8: Art de la controverse, de la dispute philosophique. | H8: =MATCH(F8,Liste!A:A,0) -> 4271
A9: Factice : Qui n'est pas naturel ; artificiel ou faux. | B9: =LEN(A9) -> 57 | C9: =SEARCH(":",A9) -> 13 | D9: =LEFT(A9,C9-2) -> Factice | E9: =LEN(D9) -> 11 | F9: Factice | G9: Qui n'est pas naturel ; artificiel ou faux. | H9: =MATCH(F9,Liste!A:A,0) -> #N/A
A10: Grivois : Qui est d'une gaieté libre, hardie, voire légèrement obscène. | B10: =LEN(A10) -> 75 | C10: =SEARCH(":",A10) -> 13 | D10: =LEFT(A10,C10-2) -> Grivois | E10: =LEN(D10) -> 11 | F10: Grivois | G10: Qui est d'une gaieté libre, hardie, voire légèrement obscène. | H10: =MATCH(F10,Liste!A:A,0) -> #N/A
A11: Hédonisme : Doctrine philosophique qui fait du plaisir le but de la vie. | B11: =LEN(A11) -> 76 | C11: =SEARCH(":",A11) -> 15 | D11: =LEFT(A11,C11-2) -> Hédonisme | E11: =LEN(D11) -> 13 | F11: Hédonisme | G11: Doctrine philosophique qui fait du plaisir le but de la vie. | H11: =MATCH(F11,Liste!A:A,0) -> #N/A
A12: Idiosyncrasie : Comportement ou réaction propre et particulière à un individu. | B12: =LEN(A12) -> 82 | C12: =SEARCH(":",A12) -> 19 | D12: =LEFT(A12,C12-2) -> Idiosyncrasie | E12: =LEN(D12) -> 17 | F12: Idiosyncrasie | G12: Comportement ou réaction propre et particulière à un individu. | H12: =MATCH(F12,Liste!A:A,0) -> #N/A
... A4642: Zymique : Qui appartient, se rapporte ou est propre aux fermentations chimiques. | B4642: =LEN(A4642) -> 84 | C4642: =SEARCH(":",A4642) -> 13 | D4642: =LEFT(A4642,C4642-2) -> Zymique | E4642: =LEN(D4642) -> 11 | F4642: Zymique | G4642: Qui appartient, se rapporte ou est propre aux fermentations chimiques. | H4642: =MATCH(F4642,Liste!A:A,0) -> 1123
A4643: Ébe (ou Jusant) : Période où la mer descend à marée basse (terme maritime). | B4643: =LEN(A4643) -> 79 | C4643: =SEARCH(":",A4643) -> 21 | D4643: =LEFT(A4643,C4643-2) -> Ébe (ou Jusant) | E4643: =LEN(D4643) -> 19 | F4643: Ébe | G4643: (ou Jusant) Période où la mer descend à marée basse (terme maritime). | H4643: =MATCH(F4643,Liste!A:A,0) -> 4770 | I4643: =LEN(F4643) -> 3 | J4643: =SEARCH(" (ou",F4643) -> #VALUE! | K4643: Ébe | L4643: (ou Jusant) Période où la mer descend à marée basse (terme maritime). | M4643: =LEFT(F4643,J4643-1) -> #VALUE! | N4643: =RIGHT(F4643,I4643-J4643)&" "&G4643 -> #VALUE!
A4644: Onc (ou Onques) : Mot de vieux français signifiant "jamais" (utilisé dans "oncques ne vit"). | B4644: =LEN(A4644) -> 96 | C4644: =SEARCH(":",A4644) -> 21 | D4644: =LEFT(A4644,C4644-2) -> Onc (ou Onques) | E4644: =LEN(D4644) -> 19 | F4644: Onc | G4644: (ou Onques) Mot de vieux français signifiant "jamais" (utilisé dans "oncques ne vit"). | H4644: =MATCH(F4644,Liste!A:A,0) -> 4195 | I4644: =LEN(F4644) -> 3 | J4644: =SEARCH(" (ou",F4644) -> #VALUE! | K4644: Onc | L4644: (ou Onques) Mot de vieux français signifiant "jamais" (utilisé dans "oncques ne vit"). | M4644: =LEFT(F4644,J4644-1) -> #VALUE! | N4644: =RIGHT(F4644,I4644-J4644)&" "&G4644 -> #VALUE!
A4645: Oue (ou Oye) : Mot de vieux français pour désigner l'oie. | B4645: =LEN(A4645) -> 61 | C4645: =SEARCH(":",A4645) -> 18 | D4645: =LEFT(A4645,C4645-2) -> Oue (ou Oye) | E4645: =LEN(D4645) -> 16 | F4645: Oue | G4645: (ou Oye) Mot de vieux français pour désigner l'oie. | H4645: =MATCH(F4645,Liste!A:A,0) -> 3663 | I4645: =LEN(F4645) -> 3 | J4645: =SEARCH(" (ou",F4645) -> #VALUE! | K4645: Oue | L4645: (ou Oye) Mot de vieux français pour désigner l'oie. | M4645: =LEFT(F4645,J4645-1) -> #VALUE! | N4645: =RIGHT(F4645,I4645-J4645)&" "&G4645 -> #VALUE!
A4646: Ure (ou Aurochs) : Bœuf sauvage préhistorique géant aujourd'hui disparu, ancêtre de nos races de bétail. | B4646: =LEN(A4646) -> 108 | C4646: =SEARCH(":",A4646) -> 22 | D4646: =LEFT(A4646,C4646-2) -> Ure (ou Aurochs) | E4646: =LEN(D4646) -> 20 | F4646: Ure | G4646: (ou Aurochs) Bœuf sauvage préhistorique géant aujourd'hui disparu, ancêtre de nos races de bétail. | H4646: =MATCH(F4646,Liste!A:A,0) -> 2453 | I4646: =LEN(F4646) -> 3 | J4646: =SEARCH(" (ou",F4646) -> #VALUE! | K4646: Ure | L4646: (ou Aurochs) Bœuf sauvage préhistorique géant aujourd'hui disparu, ancêtre de nos races de bétail. | M4646: =LEFT(F4646,J4646-1) -> #VALUE! | N4646: =RIGHT(F4646,I4646-J4646)&" "&G4646 -> #VALUE!
A4647: Yac (ou Yack) : Grand mammifère ruminant des plateaux du Tibet couvert d'une longue toison de poils laineux. | B4647: =LEN(A4647) -> 112 | C4647: =SEARCH(":",A4647) -> 19 | D4647: =LEFT(A4647,C4647-2) -> Yac (ou Yack) | E4647: =LEN(D4647) -> 17 | F4647: Yac | G4647: (ou Yack) Grand mammifère ruminant des plateaux du Tibet couvert d'une longue toison de poils laineux. | H4647: =MATCH(F4647,Liste!A:A,0) -> 1236 | I4647: =LEN(F4647) -> 3 | J4647: =SEARCH(" (ou",F4647) -> #VALUE! | K4647: Yac | L4647: (ou Yack) Grand mammifère ruminant des plateaux du Tibet couvert d'une longue toison de poils laineux. | M4647: =LEFT(F4647,J4647-1) -> #VALUE! | N4647: =RIGHT(F4647,I4647-J4647)&" "&G4647 -> #VALUE!
A4648: Zec (ou Zéquin) : Ancienne pièce de monnaie d'or frappée à Venise, très recherchée pour sa pureté autrefois. | B4648: =LEN(A4648) -> 112 | C4648: =SEARCH(":",A4648) -> 21 | D4648: =LEFT(A4648,C4648-2) -> Zec (ou Zéquin) | E4648: =LEN(D4648) -> 19 | F4648: Zec | G4648: (ou Zéquin) Ancienne pièce de monnaie d'or frappée à Venise, très recherchée pour sa pureté autrefois. | H4648: =MATCH(F4648,Liste!A:A,0) -> 2821 | I4648: =LEN(F4648) -> 3 | J4648: =SEARCH(" (ou",F4648) -> #VALUE! | K4648: Zec | L4648: (ou Zéquin) Ancienne pièce de monnaie d'or frappée à Venise, très recherchée pour sa pureté autrefois. | M4648: =LEFT(F4648,J4648-1) -> #VALUE! | N4648: =RIGHT(F4648,I4648-J4648)&" "&G4648 -> #VALUE!
A4649: Biez (ou Bief) : Canal de dérivation qui conduit l'eau d'une rivière jusqu'à la roue d'un moulin. | B4649: =LEN(A4649) -> 101 | C4649: =SEARCH(":",A4649) -> 20 | D4649: =LEFT(A4649,C4649-2) -> Biez (ou Bief) | E4649: =LEN(D4649) -> 18 | F4649: Biez | G4649: (ou Bief) Canal de dérivation qui conduit l'eau d'une rivière jusqu'à la roue d'un moulin. | H4649: =MATCH(F4649,Liste!A:A,0) -> 1610 | I4649: =LEN(F4649) -> 4 | J4649: =SEARCH(" (ou",F4649) -> #VALUE! | K4649: Biez | L4649: (ou Bief) Canal de dérivation qui conduit l'eau d'une rivière jusqu'à la roue d'un moulin. | M4649: =LEFT(F4649,J4649-1) -> #VALUE! | N4649: =RIGHT(F4649,I4649-J4649)&" "&G4649 -> #VALUE!
A4650: Glai (ou Glaie) : Sorte de plante aquatique des marais ressemblant à l'iris (le glaïeul sauvage). | B4650: =LEN(A4650) -> 101 | C4650: =SEARCH(":",A4650) -> 21 | D4650: =LEFT(A4650,C4650-2) -> Glai (ou Glaie) | E4650: =LEN(D4650) -> 19 | F4650: Glai | G4650: (ou Glaie) Sorte de plante aquatique des marais ressemblant à l'iris (le glaïeul sauvage). | H4650: =MATCH(F4650,Liste!A:A,0) -> 3613 | I4650: =LEN(F4650) -> 4 | J4650: =SEARCH(" (ou",F4650) -> #VALUE! | K4650: Glai | L4650: (ou Glaie) Sorte de plante aquatique des marais ressemblant à l'iris (le glaïeul sauvage). | M4650: =LEFT(F4650,J4650-1) -> #VALUE! | N4650: =RIGHT(F4650,I4650-J4650)&" "&G4650 -> #VALUE!
A4651: Gone (ou Gonne) : Tunique longue portée au Moyen Âge ; ou enfant dans le parler lyonnais moderne. | B4651: =LEN(A4651) -> 101 | C4651: =SEARCH(":",A4651) -> 21 | D4651: =LEFT(A4651,C4651-2) -> Gone (ou Gonne) | E4651: =LEN(D4651) -> 19 | F4651: Gone | G4651: (ou Gonne) Tunique longue portée au Moyen Âge ; ou enfant dans le parler lyonnais moderne. | H4651: =MATCH(F4651,Liste!A:A,0) -> #N/A | I4651: =LEN(F4651) -> 4 | J4651: =SEARCH(" (ou",F4651) -> #VALUE! | K4651: Gone | L4651: (ou Gonne) Tunique longue portée au Moyen Âge ; ou enfant dans le parler lyonnais moderne. | M4651: =LEFT(F4651,J4651-1) -> #VALUE! | N4651: =RIGHT(F4651,I4651-J4651)&" "&G4651 -> #VALUE!
A4652: Naye (ou Naie) : Sorte de petite cheville ou de cale en bois rustique. | B4652: =LEN(A4652) -> 74 | C4652: =SEARCH(":",A4652) -> 20 | D4652: =LEFT(A4652,C4652-2) -> Naye (ou Naie) | E4652: =LEN(D4652) -> 18 | F4652: Naye | G4652: (ou Naie) Sorte de petite cheville ou de cale en bois rustique. | H4652: =MATCH(F4652,Liste!A:A,0) -> 2891 | I4652: =LEN(F4652) -> 4 | J4652: =SEARCH(" (ou",F4652) -> #VALUE! | K4652: Naye | L4652: (ou Naie) Sorte de petite cheville ou de cale en bois rustique. | M4652: =LEFT(F4652,J4652-1) -> #VALUE! | N4652: =RIGHT(F4652,I4652-J4652)&" "&G4652 -> #VALUE!
A4653: Oing (ou Vieux oing) : Graisse de porc ou de bête purifiée servant à lubrifier les essieux des charrettes autrefois. | B4653: =LEN(A4653) -> 120 | C4653: =SEARCH(":",A4653) -> 26 | D4653: =LEFT(A4653,C4653-2) -> Oing (ou Vieux oing) | E4653: =LEN(D4653) -> 24 | F4653: Oing | G4653: (ou Vieux oing) Graisse de porc ou de bête purifiée servant à lubrifier les essieux des charrettes autrefois. | H4653: =MATCH(F4653,Liste!A:A,0) -> 10 | I4653: =LEN(F4653) -> 4 | J4653: =SEARCH(" (ou",F4653) -> #VALUE! | K4653: Oing | L4653: (ou Vieux oing) Graisse de porc ou de bête purifiée servant à lubrifier les essieux des charrettes autrefois. | M4653: =LEFT(F4653,J4653-1) -> #VALUE! | N4653: =RIGHT(F4653,I4653-J4653)&" "&G4653 -> #VALUE!
A4654: Oost (ou Ost) : L'armée ou la campagne militaire féodale au Moyen Âge en vieux français. | B4654: =LEN(A4654) -> 92 | C4654: =SEARCH(":",A4654) -> 19 | D4654: =LEFT(A4654,C4654-2) -> Oost (ou Ost) | E4654: =LEN(D4654) -> 17 | F4654: Oost | G4654: (ou Ost) L'armée ou la campagne militaire féodale au Moyen Âge en vieux français. | H4654: =MATCH(F4654,Liste!A:A,0) -> 4683 | I4654: =LEN(F4654) -> 4 | J4654: =SEARCH(" (ou",F4654) -> #VALUE! | K4654: Oost | L4654: (ou Ost) L'armée ou la campagne militaire féodale au Moyen Âge en vieux français. | M4654: =LEFT(F4654,J4654-1) -> #VALUE! | N4654: =RIGHT(F4654,I4654-J4654)&" "&G4654 -> #VALUE!
... A4914: Chryséléphantin (ou Chryséléphantine) : Statue antique faite de plaques d'or (pour les draps) et d'ivoire (pour la chair), comme la statue de Zeus à Olympie. | B4914: =LEN(A4914) -> 161 | C4914: =SEARCH(":",A4914) -> 43 | D4914: =LEFT(A4914,C4914-2) -> Chryséléphantin (ou Chryséléphantine) | E4914: =LEN(D4914) -> 41 | F4914: Chryséléphantin | G4914: (ou Chryséléphantine) Statue antique faite de plaques d'or (pour les draps) et d'ivoire (pour la chair), comme la statue de Zeus à Olympie. | H4914: =MATCH(F4914,Liste!A:A,0) -> 4436 | I4914: =LEN(F4914) -> 15 | J4914: =SEARCH(" (ou",F4914) -> #VALUE! | K4914: Chryséléphantin | L4914: (ou Chryséléphantine) Statue antique faite de plaques d'or (pour les draps) et d'ivoire (pour la chair), comme la statue de Zeus à Olympie. | M4914: =LEFT(F4914,J4914-1) -> #VALUE! | N4914: =RIGHT(F4914,I4914-J4914)&" "&G4914 -> #VALUE!
A4915: Barde (armure/cuisine) : Armure de fer protégeant le cheval de guerre ; ou mince tranche de lard enveloppant une viande. | B4915: =LEN(A4915) -> 124 | C4915: =SEARCH(":",A4915) -> 28 | D4915: =LEFT(A4915,C4915-2) -> Barde (armure/cuisine) | E4915: =LEN(D4915) -> 26 | F4915: Barde | G4915: Armure de fer protégeant le cheval de guerre ; ou mince tranche de lard enveloppant une viande. | H4915: =MATCH(F4915,Liste!A:A,0) -> 2966 | I4915: =LEN(F4915) -> 5 | J4915: =SEARCH(" (ou",F4915) -> #VALUE! | K4915: #VALUE! | L4915: #VALUE! | M4915: =LEFT(F4915,J4915-1) -> #VALUE! | N4915: =RIGHT(F4915,I4915-J4915)&" "&G4915 -> #VALUE!
A4916: Barde (poète) : Poète et chanteur celte chargé de célébrer les exploits des héros. | B4916: =LEN(A4916) -> 86 | C4916: =SEARCH(":",A4916) -> 19 | D4916: =LEFT(A4916,C4916-2) -> Barde (poète) | E4916: =LEN(D4916) -> 17 | F4916: Barde | G4916: Poète et chanteur celte chargé de célébrer les exploits des héros. | H4916: =MATCH(F4916,Liste!A:A,0) -> 2966 | I4916: =LEN(F4916) -> 5 | J4916: =SEARCH(" (ou",F4916) -> #VALUE! | K4916: #VALUE! | L4916: #VALUE! | M4916: =LEFT(F4916,J4916-1) -> #VALUE! | N4916: =RIGHT(F4916,I4916-J4916)&" "&G4916 -> #VALUE!
A4917: Eleuthénie : Fête ou célébration de la liberté dans la Grèce antique. | B4917: =LEN(A4917) -> 73 | C4917: =SEARCH(":",A4917) -> 16 | D4917: =LEFT(A4917,C4917-2) -> Eleuthénie | E4917: =LEN(D4917) -> 14 | F4917: Eleuthénie | G4917: Fête ou célébration de la liberté dans la Grèce antique. | H4917: =MATCH(F4917,Liste!A:A,0) -> #N/A | I4917: =LEN(F4917) -> 10 | J4917: =SEARCH(" (ou",F4917) -> #VALUE! | K4917: #VALUE! | L4917: #VALUE! | M4917: =LEFT(F4917,J4917-1) -> #VALUE! | N4917: =RIGHT(F4917,I4917-J4917)&" "&G4917 -> #VALUE!
A4918: Éphélide (souvent au pluriel Éphélides) : Nom scientifique et médical donné aux taches de rousseur provoquées par le soleil. | B4918: =LEN(A4918) -> 128 | C4918: =SEARCH(":",A4918) -> 45 | D4918: =LEFT(A4918,C4918-2) -> Éphélide (souvent au pluriel Éphélides) | E4918: =LEN(D4918) -> 43 | F4918: Éphélide | G4918: Nom scientifique et médical donné aux taches de rousseur provoquées par le soleil. | H4918: =MATCH(F4918,Liste!A:A,0) -> 4213 | I4918: =LEN(F4918) -> 8 | J4918: =SEARCH(" (ou",F4918) -> #VALUE! | K4918: #VALUE! | L4918: #VALUE! | M4918: =LEFT(F4918,J4918-1) -> #VALUE! | N4918: =RIGHT(F4918,I4918-J4918)&" "&G4918 -> #VALUE!
A4919: Ridel : Rideau ou draperie de séparation au Moyen Âge. | B4919: =LEN(A4919) -> 58 | C4919: =SEARCH(":",A4919) -> 11 | D4919: =LEFT(A4919,C4919-2) -> Ridel | E4919: =LEN(D4919) -> 9 | F4919: Ridel | G4919: Rideau ou draperie de séparation au Moyen Âge. | H4919: =MATCH(F4919,Liste!A:A,0) -> #N/A | I4919: =LEN(F4919) -> 5 | J4919: =SEARCH(" (ou",F4919) -> #VALUE! | K4919: #VALUE! | L4919: #VALUE! | M4919: =LEFT(F4919,J4919-1) -> #VALUE! | N4919: =RIGHT(F4919,I4919-J4919)&" "&G4919 -> #VALUE!
A4920: Sacreplumet : Homme vaniteux et fier de sa tenue en vieux français. | B4920: =LEN(A4920) -> 71 | C4920: =SEARCH(":",A4920) -> 17 | D4920: =LEFT(A4920,C4920-2) -> Sacreplumet | E4920: =LEN(D4920) -> 15 | F4920: Sacreplumet | G4920: Homme vaniteux et fier de sa tenue en vieux français. | H4920: =MATCH(F4920,Liste!A:A,0) -> #N/A | I4920: =LEN(F4920) -> 11 | J4920: =SEARCH(" (ou",F4920) -> #VALUE! | K4920: #VALUE! | L4920: #VALUE! | M4920: =LEFT(F4920,J4920-1) -> #VALUE! | N4920: =RIGHT(F4920,I4920-J4920)&" "&G4920 -> #VALUE!
A4921: Saynète : Courte pièce de théâtre comique, légère et rapide comptant peu de personnages. | B4921: =LEN(A4921) -> 92 | C4921: =SEARCH(":",A4921) -> 13 | D4921: =LEFT(A4921,C4921-2) -> Saynète | E4921: =LEN(D4921) -> 11 | F4921: Saynète | G4921: Courte pièce de théâtre comique, légère et rapide comptant peu de personnages. | H4921: =MATCH(F4921,Liste!A:A,0) -> #N/A | I4921: =LEN(F4921) -> 7 | J4921: =SEARCH(" (ou",F4921) -> #VALUE! | K4921: #VALUE! | L4921: #VALUE! | M4921: =LEFT(F4921,J4921-1) -> #VALUE! | N4921: =RIGHT(F4921,I4921-J4921)&" "&G4921 -> #VALUE!
A4922: Lambrequin (souvent au pluriel Lambrequins) : Longs rubans de tissu découpés ornant le timbre du casque d'un chevalier ; ou bordure découpée de toit. | B4922: =LEN(A4922) -> 149 | C4922: =SEARCH(":",A4922) -> 45 | D4922: =LEFT(A4922,C4922-2) -> Lambrequin (souvent au pluriel Lambrequins) | E4922: =LEN(D4922) -> 43 | F4922: Lambrequin | G4922: Longs rubans de tissu découpés ornant le timbre du casque d'un chevalier ; ou bordure découpée de toit. | H4922: =MATCH(F4922,Liste!A:A,0) -> 2132 | I4922: =LEN(F4922) -> 10 | J4922: =SEARCH(" (ou",F4922) -> #VALUE! | K4922: #VALUE! | L4922: #VALUE! | M4922: =LEFT(F4922,J4922-1) -> #VALUE! | N4922: =RIGHT(F4922,I4922-J4922)&" "&G4922 -> #VALUE!
A4923: Linéament (souvent au pluriel Linéaments) : Premiers traits d'un dessin ; ou premières ébauches d'un projet ou d'une idée. | B4923: =LEN(A4923) -> 122 | C4923: =SEARCH(":",A4923) -> 43 | D4923: =LEFT(A4923,C4923-2) -> Linéament (souvent au pluriel Linéaments) | E4923: =LEN(D4923) -> 41 | F4923: Linéament | G4923: Premiers traits d'un dessin ; ou premières ébauches d'un projet ou d'une idée. | H4923: =MATCH(F4923,Liste!A:A,0) -> 378 | I4923: =LEN(F4923) -> 9 | J4923: =SEARCH(" (ou",F4923) -> #VALUE! | K4923: #VALUE! | L4923: #VALUE! | M4923: =LEFT(F4923,J4923-1) -> #VALUE! | N4923: =RIGHT(F4923,I4923-J4923)&" "&G4923 -> #VALUE!
A4924: Voussoir : Pierre taillée en coin formant le cintre d'une arche ou d'une voûte en maçonnerie. | B4924: =LEN(A4924) -> 93 | C4924: =SEARCH(":",A4924) -> 10 | D4924: =LEFT(A4924,C4924-2) -> Voussoir | E4924: =LEN(D4924) -> 8 | F4924: Voussoir | G4924: Pierre taillée en coin formant le cintre d'une arche ou d'une voûte en maçonnerie. | H4924: =MATCH(F4924,Liste!A:A,0) -> #N/A | I4924: =LEN(F4924) -> 8 | J4924: =SEARCH(" (ou",F4924) -> #VALUE! | K4924: #VALUE! | L4924: #VALUE! | M4924: =LEFT(F4924,J4924-1) -> #VALUE! | N4924: =RIGHT(F4924,I4924-J4924)&" "&G4924 -> #VALUE!
A4925: Xénélansie : Expulsion ou interdiction d'accès faite aux étrangers dans la cité de Sparte antique. | B4925: =LEN(A4925) -> 98 | C4925: =SEARCH(":",A4925) -> 12 | D4925: =LEFT(A4925,C4925-2) -> Xénélansie | E4925: =LEN(D4925) -> 10 | F4925: Xénélansie | G4925: Expulsion ou interdiction d'accès faite aux étrangers dans la cité de Sparte antique. | H4925: =MATCH(F4925,Liste!A:A,0) -> #N/A | I4925: =LEN(F4925) -> 10 | J4925: =SEARCH(" (ou",F4925) -> #VALUE! | K4925: #VALUE! | L4925: #VALUE! | M4925: =LEFT(F4925,J4925-1) -> #VALUE! | N4925: =RIGHT(F4925,I4925-J4925)&" "&G4925 -> #VALUE!
A4926: Zélateur : Partisan fervent, défenseur plein de zèle et enthousiaste d'une cause ou d'une doctrine. | B4926: =LEN(A4926) -> 99 | C4926: =SEARCH(":",A4926) -> 10 | D4926: =LEFT(A4926,C4926-2) -> Zélateur | E4926: =LEN(D4926) -> 8 | F4926: Zélateur | G4926: Partisan fervent, défenseur plein de zèle et enthousiaste d'une cause ou d'une doctrine. | H4926: =MATCH(F4926,Liste!A:A,0) -> #N/A | I4926: =LEN(F4926) -> 8 | J4926: =SEARCH(" (ou",F4926) -> #VALUE! | K4926: #VALUE! | L4926: #VALUE! | M4926: =LEFT(F4926,J4926-1) -> #VALUE! | N4926: =RIGHT(F4926,I4926-J4926)&" "&G4926 -> #VALUE!
A4927: Pagale (En pagale) : En grand désordre, pêle-mêle (origine maritime, variante de pataquès). | B4927: =LEN(A4927) -> 91 | C4927: =SEARCH(":",A4927) -> 20 | D4927: =LEFT(A4927,C4927-2) -> Pagale (En pagale) | E4927: =LEN(D4927) -> 18 | F4927: Pagale | G4927: (En pagale) En grand désordre, pêle-mêle (origine maritime, variante de pataquès). | H4927: =MATCH(F4927,Liste!A:A,0) -> 4008 | I4927: =LEN(F4927) -> 6 | J4927: =SEARCH(" (",F4927) -> #VALUE! | K4927: Pagale | L4927: (En pagale) En grand désordre, pêle-mêle (origine maritime, variante de pataquès). | M4927: =LEFT(F4927,J4927-1) -> #VALUE! | N4927: =RIGHT(F4927,I4927-J4927)&" "&G4927 -> #VALUE!
A4928: Panader (Se panader) : Marcher fièrement en se pavanant et en prenant des airs importants. | B4928: =LEN(A4928) -> 90 | C4928: =SEARCH(":",A4928) -> 22 | D4928: =LEFT(A4928,C4928-2) -> Panader (Se panader) | E4928: =LEN(D4928) -> 20 | F4928: Panader | G4928: (Se panader) Marcher fièrement en se pavanant et en prenant des airs importants. | H4928: =MATCH(F4928,Liste!A:A,0) -> 3141 | I4928: =LEN(F4928) -> 7 | J4928: =SEARCH(" (",F4928) -> #VALUE! | K4928: Panader | L4928: (Se panader) Marcher fièrement en se pavanant et en prenant des airs importants. | M4928: =LEFT(F4928,J4928-1) -> #VALUE! | N4928: =RIGHT(F4928,I4928-J4928)&" "&G4928 -> #VALUE!
...
